<?xml version="1.0" ?>
<robot xmlns:xacro="http://www.ros.org/wiki/xacro">

<xacro:include filename="$(find quicksilver_description)/urdf/roller.urdf.xacro"/>

<xacro:macro
	name="rim_macro"
	params="name color xyz rpy">

		<link name="rim_${name}_link">
			<inertial>
				<origin xyz="0 0 -0.000343"/>
				<mass value="0.1"/>
				<inertia
					ixx="3.5882205135936479220061309613548e-5"
					ixy="0"
					ixz="0"
					iyy="3.5882205135936479220061309613548e-5"
					iyz="0"
					izz="4.2502518671672900528621921656748e-5"/>


			</inertial>
			<visual>
				<geometry>

					<mesh filename="package://quicksilver_description/mesh/rim.stl" scale="2 2 2" />
					
				</geometry>
				<material name="rim_${name}_material">
					<color rgba="${color} 1"/>
				</material>
			</visual>
			<collision>
				<geometry>
					<mesh filename="package://quicksilver_description/mesh/rim.stl" scale="2 2 2"/>
				</geometry>
			</collision>
			
		</link>

		<joint
			name="rim_${name}_joint"
			type="continuous">

			<parent link="base_link" />
			<child link="rim_${name}_link" />
			<axis xyz="0 0 1"/>
			<origin xyz="${xyz}" rpy="${rpy}"/>

		</joint>
		<xacro:roller_macro
			parent="${name}"
			name="e"
			xyz="0.0271 0 0.011"
			rpy="-1.570796326794896 0 0"
		/>
		<xacro:roller_macro
			parent="${name}"
			name="ne"
			xyz="0.01916259378 0.01916259378 -0.011"
			rpy="-1.570796326794896 0 0.7853981633974483"
		/>
		<xacro:roller_macro
			parent="${name}"
			name="n"
			xyz="0 0.0271 0.011"
			rpy="-1.570796326794896 0 1.570796326794896"
		/>
		<xacro:roller_macro
			parent="${name}"
			name="nw"
			xyz="-0.01916259378 0.01916259378 -0.011"
			rpy="-1.570796326794896 0 2.356194490192345"
		/>
		<xacro:roller_macro
			parent="${name}"
			name="w"
			xyz="-0.0271 0 0.011"
			rpy="-1.570796326794896 0 3.141592653589793"
		/>
		<xacro:roller_macro
			parent="${name}"
			name="sw"
			xyz="-0.01916259378 -0.01916259378 -0.011"
			rpy="-1.570796326794896 0 -2.356194490192345"
		/>
		<xacro:roller_macro
			parent="${name}"
			name="s"
			xyz="0 -0.0271 0.011"
			rpy="-1.570796326794896 0 -1.570796326794896"
		/>
		<xacro:roller_macro
			parent="${name}"
			name="se"
			xyz="0.01916259378 -0.01916259378 -0.011"
			rpy="-1.570796326794896 0 -0.7853981633974483"
		/>

		<transmission name="rim_${name}_transmission">
			<type>transmission_interface/SimpleTransmission</type>
			<joint name="rim_${name}_joint">
				<hardwareInterface>hardware_interface/VelocityJointInterface</hardwareInterface>
			</joint>
			<actuator name="rim_${name}_motor">
				<hardwareInterface>hardware_interface/VelocityJointInterface</hardwareInterface>
				<mechanicalReduction>1</mechanicalReduction>
			</actuator>
		</transmission>

	</xacro:macro>

</robot>
